Unknown command: 'ruserver'. Did you mean runserver?
Type 'manage.py help' for usage.
Unknown command: 'ruserver'. Did you mean runserver?
Type 'manage.py help' for usage.
Unknown command: 'ruserver'. Did you mean runserver?
Type 'manage.py help' for usage.
Watching for file changes with StatReloader
Performing system checks...

System check identified no issues (0 silenced).
September 14, 2022 - 09:12:22
Django version 4.1.1, using settings 'NativeTalkEmailBackend.settings'
Starting development server at http://127.0.0.1:8000/
Quit the server with CONTROL-C.
Watching for file changes with StatReloader
Performing system checks...

System check identified no issues (0 silenced).
September 14, 2022 - 09:47:44
Django version 4.1.1, using settings 'NativeTalkEmailBackend.settings'
Starting development server at http://0.0.0.0:8000/
Quit the server with CONTROL-C.
Traceback (most recent call last):
  File "manage.py", line 11, in main
    from django.core.management import execute_from_command_line
ModuleNotFoundError: No module named 'django'

The above exception was the direct cause of the following exception:

Traceback (most recent call last):
  File "manage.py", line 22, in <module>
    main()
  File "manage.py", line 13, in main
    raise ImportError(
ImportError: Couldn't import Django. Are you sure it's installed and available on your PYTHONPATH environment variable? Did you forget to activate a virtual environment?
Watching for file changes with StatReloader
Watching for file changes with StatReloader
[14/Sep/2022 10:16:17] "GET /sendmail/?first_name=Joseph&last_name=Olorunmeyan&business_name=L%27ayo&customer_email=jtobi8161@gmail.com&work_address=213A%20igbosere&nin_number=12345678910&did_number=9087447785&template=nativetalk_support HTTP/1.1" 200 7
[14/Sep/2022 10:16:18] "GET /sendmail/?first_name=Joseph&last_name=Olorunmeyan&business_name=L%27ayo&customer_email=jtobi8161@gmail.com&work_address=213A%20igbosere&nin_number=12345678910&did_number=9087447785&template=nativetalk_support HTTP/1.1" 200 7
[14/Sep/2022 10:16:18] "GET /sendmail/?first_name=Joseph&last_name=Olorunmeyan&business_name=L%27ayo&customer_email=jtobi8161@gmail.com&work_address=213A%20igbosere&nin_number=12345678910&did_number=9087447785&template=nativetalk_support HTTP/1.1" 200 7
[14/Sep/2022 10:16:21] "GET /sendmail/?to_name=Joseph&to_email=jtobi8161@gmail.com&template=nativetalk_user_verification HTTP/1.1" 200 7
[14/Sep/2022 10:16:22] "GET /sendmail/?to_name=Joseph&to_email=jtobi8161@gmail.com&template=nativetalk_user_verification HTTP/1.1" 200 7
[14/Sep/2022 10:16:22] "GET /sendmail/?to_name=Joseph&to_email=jtobi8161@gmail.com&template=nativetalk_user_verification HTTP/1.1" 200 7
Traceback (most recent call last):
  File "/home/tech4mation1/Jtobyy/NativeTalkEmailBackend/NativeTalkEmailBackend/settings.py", line 26, in <module>
    SECRET_KEY = os.environ['SECRET_KEY']
  File "/usr/lib/python3.8/os.py", line 675, in __getitem__
    raise KeyError(key) from None
KeyError: 'SECRET_KEY'

The above exception was the direct cause of the following exception:

Traceback (most recent call last):
  File "manage.py", line 22, in <module>
    main()
  File "manage.py", line 18, in main
    execute_from_command_line(sys.argv)
  File "/home/tech4mation1/Jtobyy/NativeTalkEmailBackend/.env/lib/python3.8/site-packages/django/core/management/__init__.py", line 446, in execute_from_command_line
    utility.execute()
  File "/home/tech4mation1/Jtobyy/NativeTalkEmailBackend/.env/lib/python3.8/site-packages/django/core/management/__init__.py", line 386, in execute
    settings.INSTALLED_APPS
  File "/home/tech4mation1/Jtobyy/NativeTalkEmailBackend/.env/lib/python3.8/site-packages/django/conf/__init__.py", line 92, in __getattr__
    self._setup(name)
  File "/home/tech4mation1/Jtobyy/NativeTalkEmailBackend/.env/lib/python3.8/site-packages/django/conf/__init__.py", line 79, in _setup
    self._wrapped = Settings(settings_module)
  File "/home/tech4mation1/Jtobyy/NativeTalkEmailBackend/.env/lib/python3.8/site-packages/django/conf/__init__.py", line 190, in __init__
    mod = importlib.import_module(self.SETTINGS_MODULE)
  File "/usr/lib/python3.8/importlib/__init__.py", line 127, in import_module
    return _bootstrap._gcd_import(name[level:], package, level)
  File "<frozen importlib._bootstrap>", line 1014, in _gcd_import
  File "<frozen importlib._bootstrap>", line 991, in _find_and_load
  File "<frozen importlib._bootstrap>", line 975, in _find_and_load_unlocked
  File "<frozen importlib._bootstrap>", line 671, in _load_unlocked
  File "<frozen importlib._bootstrap_external>", line 848, in exec_module
  File "<frozen importlib._bootstrap>", line 219, in _call_with_frames_removed
  File "/home/tech4mation1/Jtobyy/NativeTalkEmailBackend/NativeTalkEmailBackend/settings.py", line 28, in <module>
    raise RuntimeError('Could not find a SECRET_KEY in environment') from e
RuntimeError: Could not find a SECRET_KEY in environment
